Workbook

Sheet 取引基本表
A1: 令和２年（2020年）長野県産業連関表
A2: 第１表 取引基本表（生産者価格表）≪統合大分類≫ | BK2: （単位：100万円）
D3: 1 | E3: 2 | F3: 3 | G3: 4 | H3: 5 | I3: 6 | J3: 7 | K3: 8 | L3: 9 | M3: 10 | N3: 11 | O3: 12 | P3: 13 | Q3: 14 | R3: 15 | S3: 16 | T3: 17 | U3: 18 | V3: 19 | W3: 20 | X3: 21 | Y3: 22 | Z3: 23 | AA3: 24 | AB3: 25 | AC3: 26 | AD3: 27 | AE3: 28 | AF3: 29 | AG3: 30 | AH3: 31 | AI3: 32 | AJ3: 33 | AK3: 34 | AL3: 35 | AM3: 36 | AN3: 37 | AO3: 38 | AP3: 39 | AQ3: 40 | AR3: 41 | AS3: 42 | AT3: 43 | AU3: 44 | AV3: 45 | AW3: 46 | AX3: 47 | AY3: 48 | AZ3: 49 | BA3: 50 | BB3: 51 | BC3: 52 | BD3: 53 | BE3: 54 | BF3: 55 | BG3: 56 | BH3: 57 | BI3: 58 | BJ3: 59 | BK3: 60
D4: 01 | E4: 06 | F4: 11 | G4: 15 | H4: 16 | I4: 20 | J4: 21 | K4: 22 | L4: 25 | M4: 26 | N4: 27 | O4: 28 | P4: 29 | Q4: 30 | R4: 31 | S4: 32 | T4: 33 | U4: 34 | V4: 35 | W4: 39 | X4: 41 | Y4: 46 | Z4: 47 | AA4: 48 | AB4: 51 | AC4: 53 | AD4: 55 | AE4: 57 | AF4: 59 | AG4: 61 | AH4: 63 | AI4: 64 | AJ4: 65 | AK4: 66 | AL4: 67 | AM4: 68 | AN4: 69 | AO4: 70 | AP4: 71 | AQ4: 72 | AR4: 73 | AS4: 74 | AT4: 75 | AU4: 76 | AV4: 78 | AW4: 79 | AX4: 80 | AY4: 81 | AZ4: 98 | BA4: 99 | BB4: 82 | BC4: 83 | BD4: 84 | BE4: 85 | BF4: 86 | BG4: 87 | BH4: 100 | BI4: 101 | BJ4: 88 | BK4: 97
C5: 統合大分類（37部門） | D5: 農林漁業 | E5: 鉱業 | F5: 飲食料品 | G5: 繊維製品 | H5: パルプ・紙・木製品 | I5: 化学製品 | J5: 石油・石炭製品 | K5: プラスチック・ゴム製品 | L5: 窯業・土石製品 | M5: 鉄鋼 | N5: 非鉄金属 | O5: 金属製品 | P5: はん用機械 | Q5: 生産用機械 | R5: 業務用機械 | S5: 電子部品 | T5: 電気機械 | U5: 情報通信機器 | V5: 輸送機械 | W5: その他の製造工業製品 | X5: 建設 | Y5: 電気・ガス・熱供給 | Z5: 水道 | AA5: 廃棄物処理 | AB5: 商業 | AC5: 金融・保険 | AD5: 不動産 | AE5: 運輸・郵便 | AF5: 情報通信 | AG5: 公務 | AH5: 教育・研究 | AI5: 医療・福祉 | AJ5: 他に分類されない会員制団体 | AK5: 対事業所サービス | AL5: 対個人サービス | AM5: 事務用品 | AN5: 分類不明 | AO5: 内生部門計 | AP5: 家計外消費支出（列） | AQ5: 民間消費支出 | AR5: 一般政府消費支出 | AS5: 県内総固定資本形成（公的） | AT5: 県内総固定資本形成（民間） | AU5: 在庫純増 | AV5: 県内最終需要計 | AW5: 県内需要合計 | AX5: 輸出 | AY5: 輸出計 | AZ5: 移出 | BA5: 移輸出計 | BB5: 最終需要計 | BC5: 需要合計 | BD5: （控除）輸入 | BE5: （控除）関税 | BF5: （控除）輸入品商品税 | BG5: （控除）輸入計 | BH5: （控除）移入 | BI5: （控除）移輸入計 | BJ5: 最終需要部門計 | BK5: 県内生産額
A6: 1 | B6: 01 | C6: 農林漁業 | D6: 39833 | E6: 0 | F6: 103265 | G6: 154 | H6: 3073 | I6: 318 | J6: 0 | K6: 129 | L6: 42 | M6: 0 | N6: 0 | O6: 0 | P6: 0 | Q6: 0 | R6: 0 | S6: 0 | T6: 0 | U6: 0 | V6: 0 | W6: 982 | X6: 1196 | Y6: 0 | Z6: 0 | AA6: 0 | AB6: 186 | AC6: 0 | AD6: 6 | AE6: 0 | AF6: 0 | AG6: 8 | AH6: 1107 | AI6: 2693 | AJ6: 269 | AK6: 8 | AL6: 10958 | AM6: 0 | AN6: 0 | AO6: 164227 | AP6: 988 | AQ6: 52417 | AR6: 0 | AS6: 0 | AT6: 3342 | AU6: 3736 | AV6: 60483 | AW6: 224710 | AX6: 2244 | AY6: 2244 | AZ6: 243659 | BA6: 245903 | BB6: 306386 | BC6: 470613 | BD6: -26197 | BE6: -592 | BF6: -2274 | BG6: -29063 | BH6: -88334 | BI6: -117397 | BJ6: 188989 | BK6: 353216
A7: 2 | B7: 06 | C7: 鉱業 | D7: 16 | E7: 0 | F7: 178 | G7: 0 | H7: 97 | I7: 480 | J7: 393 | K7: 6 | L7: 3537 | M7: 4 | N7: 2396 | O7: 24 | P7: 20 | Q7: 29 | R7: 13 | S7: 88 | T7: 3 | U7: 1 | V7: 38 | W7: 77 | X7: 2614 | Y7: 12112 | Z7: 0 | AA7: 0 | AB7: 2 | AC7: 0 | AD7: 0 | AE7: 1 | AF7: 0 | AG7: 2 | AH7: 27 | AI7: 7 | AJ7: 5 | AK7: 3 | AL7: 3 | AM7: 0 | AN7: 9 | AO7: 22185 | AP7: -69 | AQ7: -74 | AR7: 0 | AS7: 0 | AT7: -70 | AU7: 430 | AV7: 217 | AW7: 22402 | AX7: 50 | AY7: 50 | AZ7: 123 | BA7: 173 | BB7: 390 | BC7: 22575 | BD7: -15007 | BE7: 0 | BF7: -2085 | BG7: -17092 | BH7: -1264 | BI7: -18356 | BJ7: -17966 | BK7: 4219
A8: 3 | B8: 11 | C8: 飲食料品 | D8: 14938 | E8: 0 | F8: 155358 | G8: 46 | H8: 134 | I8: 1618 | J8: 0 | K8: 4 | L8: 54 | M8: 0 | N8: 0 | O8: 0 | P8: 0 | Q8: 0 | R8: 0 | S8: 0 | T8: 0 | U8: 0 | V8: 0 | W8: 257 | X8: 23 | Y8: 0 | Z8: 0 | AA8: 0 | AB8: 166 | AC8: 0 | AD8: 0 | AE8: 0 | AF8: 0 | AG8: 449 | AH8: 4309 | AI8: 9579 | AJ8: 199 | AK8: 3 | AL8: 65778 | AM8: 0 | AN8: 269 | AO8: 253184 | AP8: 12827 | AQ8: 418802 | AR8: 0 | AS8: 0 | AT8: 0 | AU8: -2534 | AV8: 429095 | AW8: 682279 | AX8: 8806 | AY8: 8806 | AZ8: 543380 | BA8: 552186 | BB8: 981281 | BC8: 1234465 | BD8: -82712 | BE8: -5453 | BF8: -22605 | BG8: -110770 | BH8: -438823 | BI8: -549593 | BJ8: 431688 | BK8: 684872
A9: 4 | B9: 15 | C9: 繊維製品 | D9: 910 | E9: 11 | F9: 538 | G9: 2958 | H9: 259 | I9: 214 | J9: 4 | K9: 313 | L9: 398 | M9: 29 | N9: 209 | O9: 323 | P9: 384 | Q9: 799 | R9: 281 | S9: 2497 | T9: 700 | U9: 522 | V9: 328 | W9: 1229 | X9: 3849 | Y9: 90 | Z9: 79 | AA9: 271 | AB9: 5074 | AC9: 662 | AD9: 49 | AE9: 662 | AF9: 344 | AG9: 2831 | AH9: 289 | AI9: 4555 | AJ9: 2876 | AK9: 1594 | AL9: 2797 | AM9: 467 | AN9: 15 | AO9: 39410 | AP9: 1766 | AQ9: 54394 | AR9: 0 | AS9: 14 | AT9: 2572 | AU9: -1468 | AV9: 57278 | AW9: 96688 | AX9: 1340 | AY9: 1340 | AZ9: 9478 | BA9: 10818 | BB9: 68096 | BC9: 107506 | BD9: -57156 | BE9: -2887 | BF9: -5932 | BG9: -65975 | BH9: -27068 | BI9: -93043 | BJ9: -24947 | BK9: 14463
A10: 5 | B10: 16 | C10: パルプ・紙・木製品 | D10: 18245 | E10: 2 | F10: 12104 | G10: 71 | H10: 36940 | I10: 3458 | J10: 6 | K10: 1088 | L10: 1787 | M10: 36 | N10: 335 | O10: 708 | P10: 559 | Q10: 653 | R10: 906 | S10: 3344 | T10: 1769 | U10: 2801 | V10: 457 | W10: 9319 | X10: 49839 | Y10: 268 | Z10: 347 | AA10: 455 | AB10: 8645 | AC10: 2246 | AD10: 525 | AE10: 2241 | AF10: 5572 | AG10: 797 | AH10: 4923 | AI10: 8034 | AJ10: 2357 | AK10: 4056 | AL10: 2956 | AM10: 10051 | AN10: 42 | AO10: 197942 | AP10: 1370 | AQ10: 7212 | AR10: 28 | AS10: 169 | AT10: 4792 | AU10: -2233 | AV10: 11338 | AW10: 209280 | AX10: 744 | AY10: 744 | AZ10: 63255 | BA10: 63999 | BB10: 75337 | BC10: 273279 | BD10: -27925 | BE10: -321 | BF10: -2821 | BG10: -31067 | BH10: -117854 | BI10: -148921 | BJ10: -73584 | BK10: 124358
A11: 6 | B11: 20 | C11: 化学製品 | D11: 16738 | E11: 14 | F11: 8481 | G11: 1492 | H11: 3045 | I11: 30996 | J11: 298 | K11: 32236 | L11: 9199 | M11: 119 | N11: 1136 | O11: 2663 | P11: 1358 | Q11: 2284 | R11: 1696 | S11: 7150 | T11: 2730 | U11: 4755 | V11: 4392 | W11: 5185 | X11: 5275 | Y11: 169 | Z11: 834 | AA11: 1546 | AB11: 12 | AC11: 13 | AD11: 45 | AE11: 279 | AF11: 432 | AG11: 556 | AH11: 6801 | AI11: 175767 | AJ11: 291 | AK11: 3678 | AL11: 5343 | AM11: 217 | AN11: 252 | AO11: 337477 | AP11: 2988 | AQ11: 39172 | AR11: 0 | AS11: 0 | AT11: 0 | AU11: 2632 | AV11: 44792 | AW11: 382269 | AX11: 23789 | AY11: 23789 | AZ11: 100848 | BA11: 124637 | BB11: 169429 | BC11: 506906 | BD11: -90459 | BE11: -573 | BF11: -9083 | BG11: -100115 | BH11: -273712 | BI11: -373827 | BJ11: -204398 | BK11: 133079
A12: 7 | B12: 21 | C12: 石油・石炭製品 | D12: 3862 | E12: 91 | F12: 2393 | G12: 48 | H12: 295 | I12: 718 | J12: 1920 | K12: 180 | L12: 4161 | M12: 374 | N12: 626 | O12: 1258 | P12: 357 | Q12: 544 | R12: 180 | S12: 827 | T12: 192 | U12: 116 | V12: 1156 | W12: 366 | X12: 14667 | Y12: 1340 | Z12: 1158 | AA12: 1227 | AB12: 1709 | AC12: 272 | AD12: 410 | AE12: 81841 | AF12: 399 | AG12: 4549 | AH12: 2089 | AI12: 3052 | AJ12: 424 | AK12: 1758 | AL12: 2738 | AM12: 0 | AN12: 660 | AO12: 137957 | AP12: 229 | AQ12: 103489 | AR12: 0 | AS12: 0 | AT12: 0 | AU12: 329 | AV12: 104047 | AW12: 242004 | AX12: 12 | AY12: 12 | AZ12: 42 | BA12: 54 | BB12: 104101 | BC12: 242058 | BD12: -20008 | BE12: -114 | BF12: -4000 | BG12: -24122 | BH12: -209819 | BI12: -233941 | BJ12: -129840 | BK12: 8117
A13: 8 | B13: 22 | C13: プラスチック・ゴム製品 | D13: 5363 | E13: 15 | F13: 20869 | G13: 157 | H13: 1955 | I13: 6957 | J13: 6 | K13: 42965 | L13: 468 | M13: 14 | N13: 748 | O13: 839 | P13: 3648 | Q13: 11607 | R13: 8742 | S13: 8481 | T13: 7132 | U13: 20453 | V13: 16764 | W13: 8051 | X13: 16172 | Y13: 0 | Z13: 3734 | AA13: 2045 | AB13: 6937 | AC13: 1235 | AD13: 762 | AE13: 2904 | AF13: 1267 | AG13: 1029 | AH13: 2925 | AI13: 2711 | AJ13: 977 | AK13: 10655 | AL13: 1584 | AM13: 1072 | AN13: 143 | AO13: 221386 | AP13: 359 | AQ13: 12198 | AR13: 48 | AS13: 0 | AT13: -8 | AU13: -1475 | AV13: 11122 | AW13: 232508 | AX13: 30787 | AY13: 30787 | AZ13: 141785 | BA13: 172572 | BB13: 183694 | BC13: 405080 | BD13: -26745 | BE13: -678 | BF13: -2742 | BG13: -30165 | BH13: -178286 | BI13: -208451 | BJ13: -24757 | BK13: 196629
A14: 9 | B14: 25 | C14: 窯業・土石製品 | D14: 1144 | E14: 0 | F14: 1615 | G14: 7 | H14: 174 | I14: 1733 | J14: 209 | K14: 598 | L14: 12289 | M14: 185 | N14: 2122 | O14: 1574 | P14: 2494 | Q14: 2509 | R14: 9474 | S14: 30339 | T14: 2062 | U14: 1102 | V14: 905 | W14: 977 | X14: 59962 | Y14: 30 | Z14: 501 | AA14: 50 | AB14: 244 | AC14: 6 | AD14: 93 | AE14: 15 | AF14: 4 | AG14: 141 | AH14: 1218 | AI14: 1002 | AJ14: 59 | AK14: 1116 | AL14: 670 | AM14: 125 | AN14: 192 | AO14: 136940 | AP14: 144 | AQ14: 1250 | AR14: 0 | AS14: 0 | AT14: 0 | AU14: -6661 | AV14: -5267 | AW14: 131673 | AX14: 30764 | AY14: 30764 | AZ14: 61832 | BA14: 92596 | BB14: 87329 | BC14: 224269 | BD14: -12229 | BE14: -38 | BF14: -1226 | BG14: -13493 | BH14: -73514 | BI14: -87007 | BJ14: 322 | BK14: 137262
A15: 10 | B15: 26 | C15: 鉄鋼 | D15: 14 | E15: 9 | F15: 0 | G15: 3 | H15: 1507 | I15: 0 | J15: 0 | K15: 320 | L15: 535 | M15: 11774 | N15: 144 | O15: 55511 | P15: 26986 | Q15: 50384 | R15: 3343 | S15: 4437 | T15: 11226 | U15: 4129 | V15: 18692 | W15: 1070 | X15: 21826 | Y15: 0 | Z15: 3 | AA15: 0 | AB15: 0 | AC15: 0 | AD15: 0 | AE15: 83 | AF15: 0 | AG15: 12 | AH15: 0 | AI15: 4 | AJ15: 1 | AK15: 165 | AL15: 20 | AM15: 1 | AN15: 174 | AO15: 212373 | AP15: 0 | AQ15: -480 | AR15: 0 | AS15: -475 | AT15: -2279 | AU15: -1673 | AV15: -4907 | AW15: 207466 | AX15: 5809 | AY15: 5809 | AZ15: 15481 | BA15: 21290 | BB15: 16383 | BC15: 228756 | BD15: -10213 | BE15: 0 | BF15: -1021 | BG15: -11234 | BH15: -184564 | BI15: -195798 | BJ15: -179415 | BK15: 32958
A16: 11 | B16: 27 | C16: 非鉄金属 | D16: 0 | E16: 0 | F16: 1007 | G16: 0 | H16: 369 | I16: 582 | J16: 0 | K16: 508 | L16: 1751 | M16: 40 | N16: 52018 | O16: 10478 | P16: 9150 | Q16: 11972 | R16: 8203 | S16: 36367 | T16: 15530 | U16: 19947 | V16: 13606 | W16: 2802 | X16: 9718 | Y16: 263 | Z16: 20 | AA16: 0 | AB16: 15 | AC16: 0 | AD16: 0 | AE16: 1 | AF16: 49 | AG16: 83 | AH16: 66 | AI16: 1821 | AJ16: 27 | AK16: 325 | AL16: 248 | AM16: 22 | AN16: 152 | AO16: 197140 | AP16: 20 | AQ16: 2731 | AR16: 0 | AS16: 0 | AT16: -2219 | AU16: -1363 | AV16: -831 | AW16: 196309 | AX16: 16907 | AY16: 16907 | AZ16: 69942 | BA16: 86849 | BB16: 86018 | BC16: 283158 | BD16: -65390 | BE16: -172 | BF16: -6556 | BG16: -72118 | BH16: -112770 | BI16: -184888 | BJ16: -98870 | BK16: 98270
A17: 12 | B17: 28 | C17: 金属製品 | D17: 823 | E17: 38 | F17: 9275 | G17: 20 | H17: 1753 | I17: 2338 | J17: 1 | K17: 695 | L17: 1155 | M17: 230 | N17: 457 | O17: 17633 | P17: 10620 | Q17: 18972 | R17: 7769 | S17: 16367 | T17: 7718 | U17: 13929 | V17: 4313 | W17: 2112 | X17: 91876 | Y17: 218 | Z17: 70 | AA17: 15 | AB17: 3063 | AC17: 56 | AD17: 384 | AE17: 602 | AF17: 235 | AG17: 1769 | AH17: 144 | AI17: 452 | AJ17: 292 | AK17: 1035 | AL17: 1496 | AM17: 9 | AN17: 210 | AO17: 218144 | AP17: 463 | AQ17: 4747 | AR17: 6 | AS17: 488 | AT17: 7201 | AU17: -4016 | AV17: 8889 | AW17: 227033 | AX17: 9711 | AY17: 9711 | AZ17: 191521 | BA17: 201232 | BB17: 210121 | BC17: 428265 | BD17: -19488 | BE17: -147 | BF17: -1963 | BG17: -21598 | BH17: -140872 | BI17: -162470 | BJ17: 47651 | BK17: 265795
... A43: 38 | B43: 70 | C43: 内生部門計 | D43: 183051 | E43: 2519 | F43: 459043 | G43: 8460 | H43: 75827 | I43: 79250 | J43: 4312 | K43: 113591 | L43: 74776 | M43: 19762 | N43: 79763 | O43: 131828 | P43: 151109 | Q43: 316105 | R43: 123270 | S43: 418801 | T43: 167252 | U43: 295053 | V43: 252727 | W43: 95460 | X43: 593077 | Y43: 134995 | Z43: 53434 | AA43: 36292 | AB43: 375750 | AC43: 184626 | AD43: 204980 | AE43: 355387 | AF43: 244601 | AG43: 173479 | AH43: 209940 | AI43: 491375 | AJ43: 49433 | AK43: 349260 | AL43: 298669 | AM43: 23247 | AN43: 24600 | AO43: 6855104 | AP43: 142618 | AQ43: 4298372 | AR43: 1931700 | AS43: 590542 | AT43: 1964405 | AU43: -48327 | AV43: 8879310 | AW43: 15734414 | AX43: 1356785 | AY43: 1356785 | AZ43: 3860508 | BA43: 5217293 | BB43: 14096603 | BC43: 20951707 | BD43: -1163759 | BE43: -12120 | BF43: -113283 | BG43: -1289162 | BH43: -4791255 | BI43: -6080417 | BJ43: 8016186 | BK43: 14871290
A44: 39 | B44: 71 | C44: 家計外消費支出（行） | D44: 1118 | E44: 46 | F44: 4080 | G44: 127 | H44: 1285 | I44: 1168 | J44: 47 | K44: 2747 | L44: 1593 | M44: 102 | N44: 638 | O44: 3254 | P44: 3064 | Q44: 5821 | R44: 2385 | S44: 6099 | T44: 3200 | U44: 6379 | V44: 2056 | W44: 1945 | X44: 13715 | Y44: 3441 | Z44: 787 | AA44: 1727 | AB44: 15852 | AC44: 12166 | AD44: 1554 | AE44: 3888 | AF44: 3125 | AG44: 5255 | AH44: 2099 | AI44: 10173 | AJ44: 4392 | AK44: 7873 | AL44: 9278 | AM44: 0 | AN44: 139 | AO44: 142618
A45: 40 | B45: 91 | C45: 雇用者所得 | D45: 70955 | E45: 1128 | F45: 95243 | G45: 4192 | H45: 22559 | I45: 14329 | J45: 705 | K45: 45641 | L45: 31362 | M45: 5452 | N45: 14590 | O45: 79206 | P45: 78866 | Q45: 163371 | R45: 58283 | S45: 166351 | T45: 58982 | U45: 76192 | V45: 64621 | W45: 48562 | X45: 391721 | Y45: 35560 | Z45: 11217 | AA45: 45198 | AB45: 508349 | AC45: 147163 | AD45: 53150 | AE45: 165926 | AF45: 84877 | AG45: 218994 | AH45: 323326 | AI45: 648290 | AJ45: 66457 | AK45: 321420 | AL45: 194656 | AM45: 0 | AN45: 516 | AO45: 4317410
A46: 41 | B46: 92 | C46: 営業余剰 | D46: 45577 | E46: -154 | F46: 63416 | G46: -110 | H46: 12134 | I46: 7166 | J46: 1703 | K46: 11879 | L46: 10346 | M46: 5180 | N46: -453 | O46: 17518 | P46: 27278 | Q46: 40506 | R46: 1384 | S46: -52843 | T46: -2558 | U46: -5818 | V46: -4466 | W46: 3307 | X46: 29324 | Y46: -50434 | Z46: 9638 | AA46: 4272 | AB46: 81100 | AC46: 106640 | AD46: 468325 | AE46: 25615 | AF46: 67684 | AG46: -3566 | AH46: 6934 | AI46: 9765 | AJ46: -1900 | AK46: 56156 | AL46: -3494 | AM46: 0 | AN46: 39765 | AO46: 1026816
A47: 42 | B47: 93 | C47: 資本減耗引当 | D47: 51927 | E47: 460 | F47: 42994 | G47: 1490 | H47: 7630 | I47: 29658 | J47: 973 | K47: 18036 | L47: 14616 | M47: 1296 | N47: 2838 | O47: 23320 | P47: 30583 | Q47: 72026 | R47: 31432 | S47: 100166 | T47: 48289 | U47: 90983 | V47: 38343 | W47: 20541 | X47: 59024 | Y47: 145038 | Z47: 19246 | AA47: 7774 | AB47: 112742 | AC47: 37199 | AD47: 440573 | AE47: 53117 | AF47: 77527 | AG47: 234922 | AH47: 112033 | AI47: 69003 | AJ47: 5442 | AK47: 88831 | AL47: 85560 | AM47: 0 | AN47: 2445 | AO47: 2178077
A48: 43 | B48: 94 | C48: 間接税（関税・輸入品商品税を除く。） | D48: 9697 | E48: 220 | F48: 21110 | G48: 304 | H48: 4923 | I48: 1508 | J48: 377 | K48: 4735 | L48: 4569 | M48: 1166 | N48: 894 | O48: 10671 | P48: 1772 | Q48: 2777 | R48: -9472 | S48: -10087 | T48: -7385 | U48: -20947 | V48: -1026 | W48: 2159 | X48: 54956 | Y48: 13492 | Z48: 3605 | AA48: 4292 | AB48: 67073 | AC48: 8408 | AD48: 90508 | AE48: 22223 | AF48: 14463 | AG48: 1121 | AH48: 5096 | AI48: 12117 | AJ48: 3943 | AK48: 45919 | AL48: 30035 | AM48: 0 | AN48: 2287 | AO48: 397503
A49: 44 | B49: 95 | C49: （控除）経常補助金 | D49: -9109 | E49: 0 | F49: -1014 | G49: 0 | H49: 0 | I49: 0 | J49: 0 | K49: 0 | L49: 0 | M49: 0 | N49: 0 | O49: -2 | P49: -1 | Q49: -1 | R49: -1 | S49: -4 | T49: 0 | U49: -1 | V49: -2 | W49: 0 | X49: -5522 | Y49: -56 | Z49: -3282 | AA49: 0 | AB49: -835 | AC49: -6186 | AD49: -169 | AE49: -1409 | AF49: -2 | AG49: 0 | AH49: -1187 | AI49: -14824 | AJ49: -2400 | AK49: -25 | AL49: 0 | AM49: 0 | AN49: -206 | AO49: -46238
A50: 45 | B50: 96 | C50: 粗付加価値部門計 | D50: 170165 | E50: 1700 | F50: 225829 | G50: 6003 | H50: 48531 | I50: 53829 | J50: 3805 | K50: 83038 | L50: 62486 | M50: 13196 | N50: 18507 | O50: 133967 | P50: 141562 | Q50: 284500 | R50: 84011 | S50: 209682 | T50: 100528 | U50: 146788 | V50: 99526 | W50: 76514 | X50: 543218 | Y50: 147041 | Z50: 41211 | AA50: 63263 | AB50: 784281 | AC50: 305390 | AD50: 1053941 | AE50: 269360 | AF50: 247674 | AG50: 456726 | AH50: 448301 | AI50: 734524 | AJ50: 75934 | AK50: 520174 | AL50: 316035 | AM50: 0 | AN50: 44946 | AO50: 8016186
A51: 46 | B51: 97 | C51: 県内生産額 | D51: 353216 | E51: 4219 | F51: 684872 | G51: 14463 | H51: 124358 | I51: 133079 | J51: 8117 | K51: 196629 | L51: 137262 | M51: 32958 | N51: 98270 | O51: 265795 | P51: 292671 | Q51: 600605 | R51: 207281 | S51: 628483 | T51: 267780 | U51: 441841 | V51: 352253 | W51: 171974 | X51: 1136295 | Y51: 282036 | Z51: 94645 | AA51: 99555 | AB51: 1160031 | AC51: 490016 | AD51: 1258921 | AE51: 624747 | AF51: 492275 | AG51: 630205 | AH51: 658241 | AI51: 1225899 | AJ51: 125367 | AK51: 869434 | AL51: 614704 | AM51: 23247 | AN51: 69546 | AO51: 14871290

Sheet 投入係数表
A1: 令和２年（2020年）長野県産業連関表
A2: 第２表 投入係数表
D3: 1 | E3: 2 | F3: 3 | G3: 4 | H3: 5 | I3: 6 | J3: 7 | K3: 8 | L3: 9 | M3: 10 | N3: 11 | O3: 12 | P3: 13 | Q3: 14 | R3: 15 | S3: 16 | T3: 17 | U3: 18 | V3: 19 | W3: 20 | X3: 21 | Y3: 22 | Z3: 23 | AA3: 24 | AB3: 25 | AC3: 26 | AD3: 27 | AE3: 28 | AF3: 29 | AG3: 30 | AH3: 31 | AI3: 32 | AJ3: 33 | AK3: 34 | AL3: 35 | AM3: 36 | AN3: 37 | AO3: 38 | AP3: 39 | AQ3: 40 | AR3: 41 | AS3: 42 | AT3: 43 | AU3: 44 | AV3: 45 | AW3: 46 | AX3: 47 | AY3: 48 | AZ3: 49 | BA3: 50 | BB3: 51 | BC3: 52 | BD3: 53 | BE3: 54 | BF3: 55 | BG3: 56 | BH3: 57 | BI3: 58 | BJ3: 59 | BK3: 60
D4: 01 | E4: 06 | F4: 11 | G4: 15 | H4: 16 | I4: 20 | J4: 21 | K4: 22 | L4: 25 | M4: 26 | N4: 27 | O4: 28 | P4: 29 | Q4: 30 | R4: 31 | S4: 32 | T4: 33 | U4: 34 | V4: 35 | W4: 39 | X4: 41 | Y4: 46 | Z4: 47 | AA4: 48 | AB4: 51 | AC4: 53 | AD4: 55 | AE4: 57 | AF4: 59 | AG4: 61 | AH4: 63 | AI4: 64 | AJ4: 65 | AK4: 66 | AL4: 67 | AM4: 68 | AN4: 69 | AO4: 70 | AP4: 71 | AQ4: 72 | AR4: 73 | AS4: 74 | AT4: 75 | AU4: 76 | AV4: 78 | AW4: 79 | AX4: 80 | AY4: 81 | AZ4: 98 | BA4: 99 | BB4: 82 | BC4: 83 | BD4: 84 | BE4: 85 | BF4: 86 | BG4: 87 | BH4: 100 | BI4: 101 | BJ4: 88 | BK4: 97
C5: 統合大分類（37部門） | D5: 農林漁業 | E5: 鉱業 | F5: 飲食料品 | G5: 繊維製品 | H5: パルプ・紙・木製品 | I5: 化学製品 | J5: 石油・石炭製品 | K5: プラスチック・ゴム製品 | L5: 窯業・土石製品 | M5: 鉄鋼 | N5: 非鉄金属 | O5: 金属製品 | P5: はん用機械 | Q5: 生産用機械 | R5: 業務用機械 | S5: 電子部品 | T5: 電気機械 | U5: 情報通信機器 | V5: 輸送機械 | W5: その他の製造工業製品 | X5: 建設 | Y5: 電気・ガス・熱供給 | Z5: 水道 | AA5: 廃棄物処理 | AB5: 商業 | AC5: 金融・保険 | AD5: 不動産 | AE5: 運輸・郵便 | AF5: 情報通信 | AG5: 公務 | AH5: 教育・研究 | AI5: 医療・福祉 | AJ5: 他に分類されない会員制団体 | AK5: 対事業所サービス | AL5: 対個人サービス | AM5: 事務用品 | AN5: 分類不明 | AO5: 内生部門計 | AP5: 家計外消費支出（列） | AQ5: 民間消費支出 | AR5: 一般政府消費支出 | AS5: 県内総固定資本形成（公的） | AT5: 県内総固定資本形成（民間） | AU5: 在庫純増 | AV5: 県内最終需要計 | AW5: 県内需要合計 | AX5: 輸出 | AY5: 輸出計 | AZ5: 移出 | BA5: 移輸出計 | BB5: 最終需要計 | BC5: 需要合計 | BD5: （控除）輸入 | BE5: （控除）関税 | BF5: （控除）輸入品商品税 | BG5: （控除）輸入計 | BH5: （控除）移入 | BI5: （控除）移輸入計 | BJ5: 最終需要部門計 | BK5: 県内生産額
A6: 1 | B6: 01 | C6: 農林漁業 | D6: 0.11277235 | E6: 0 | F6: 0.15078 | G6: 0.01064786 | H6: 0.024710915 | I6: 0.0023895581 | J6: 0 | K6: 0.00065605786 | L6: 0.00030598418 | M6: 0 | N6: 0 | O6: 0 | P6: 0 | Q6: 0 | R6: 0 | S6: 0 | T6: 0 | U6: 0 | V6: 0 | W6: 0.0057101655 | X6: 0.0010525436 | Y6: 0 | Z6: 0 | AA6: 0 | AB6: 0.00016034054 | AC6: 0 | AD6: 4.7659861e-06 | AE6: 0 | AF6: 0 | AG6: 1.2694282e-05 | AH6: 0.0016817549 | AI6: 0.0021967552 | AJ6: 0.0021457002 | AK6: 9.2013885e-06 | AL6: 0.017826466 | AM6: 0 | AN6: 0 | AO6: 0.011043225 | AP6: 0.0069275968 | AQ6: 0.012194617 | AR6: 0 | AS6: 0 | AT6: 0.0017012785 | AU6: -0.077306682 | AV6: 0.0068116779 | AW6: 0.014281434 | AX6: 0.0016539098 | AY6: 0.0016539098 | AZ6: 0.063115787 | BA6: 0.047132296 | BB6: 0.02173474 | BC6: 0.022461798 | BD6: 0.022510674 | BE6: 0.048844884 | BF6: 0.020073621 | BG6: 0.022544102 | BH6: 0.018436506 | BI6: 0.019307393 | BJ6: 0.023575925 | BK6: 0.023751537
A7: 2 | B7: 06 | C7: 鉱業 | D7: 4.5298061e-05 | E7: 0 | F7: 0.00025990258 | G7: 0 | H7: 0.00078000611 | I7: 0.0036068801 | J7: 0.048416903 | K7: 3.0514319e-05 | L7: 0.025768239 | M7: 0.00012136659 | N7: 0.024381805 | O7: 9.0295152e-05 | P7: 6.8336118e-05 | Q7: 4.8284646e-05 | R7: 6.2716795e-05 | S7: 0.0001400197 | T7: 1.1203227e-05 | U7: 2.2632576e-06 | V7: 0.00010787701 | W7: 0.0004477421 | X7: 0.0023004589 | Y7: 0.042944872 | Z7: 0 | AA7: 0 | AB7: 1.7240919e-06 | AC7: 0 | AD7: 0 | AE7: 1.6006479e-06 | AF7: 0 | AG7: 3.1735705e-06 | AH7: 4.1018411e-05 | AI7: 5.7100952e-06 | AJ7: 3.9882904e-05 | AK7: 3.4505207e-06 | AL7: 4.8803977e-06 | AM7: 0 | AN7: 0.00012941075 | AO7: 0.0014918006 | AP7: -0.0004838099 | AQ7: -1.721582e-05 | AR7: 0 | AS7: 0 | AT7: -3.56342e-05 | AU7: -0.0088977176 | AV7: 2.4438836e-05 | AW7: 0.0014237581 | AX7: 3.6851823e-05 | AY7: 3.6851823e-05 | AZ7: 3.1861092e-05 | BA7: 3.3158958e-05 | BB7: 2.766624e-05 | BC7: 0.0010774778 | BD7: 0.012895282 | BE7: 0 | BF7: 0.018405233 | BG7: 0.013258225 | BH7: 0.00026381397 | BI7: 0.0030188719 | BJ7: -0.0022412155 | BK7: 0.00028370101
A8: 3 | B8: 11 | C8: 飲食料品 | D8: 0.042291402 | E8: 0 | F8: 0.22684239 | G8: 0.0031805296 | H8: 0.0010775342 | I8: 0.012158192 | J8: 0 | K8: 2.0342879e-05 | L8: 0.00039340823 | M8: 0 | N8: 0 | O8: 0 | P8: 0 | Q8: 0 | R8: 0 | S8: 0 | T8: 0 | U8: 0 | V8: 0 | W8: 0.0014944119 | X8: 2.0241223e-05 | Y8: 0 | Z8: 0 | AA8: 0 | AB8: 0.00014309962 | AC8: 0 | AD8: 0 | AE8: 0 | AF8: 0 | AG8: 0.00071246658 | AH8: 0.0065462346 | AI8: 0.0078138574 | AJ8: 0.0015873396 | AK8: 3.4505207e-06 | AL8: 0.1070076 | AM8: 0 | AN8: 0.0038679435 | AO8: 0.017025019 | AP8: 0.089939559 | AQ8: 0.097432702 | AR8: 0 | AS8: 0 | AT8: 0 | AU8: 0.052434457 | AV8: 0.048325264 | AW8: 0.043362212 | AX8: 0.006490343 | AY8: 0.006490343 | AZ8: 0.1407535 | BA8: 0.10583764 | BB8: 0.069611168 | BC8: 0.058919543 | BD8: 0.071073135 | BE8: 0.44991749 | BF8: 0.1995445 | BG8: 0.085924034 | BH8: 0.091588321 | BI8: 0.090387386 | BJ8: 0.053852044 | BK8: 0.046053301
A9: 4 | B9: 15 | C9: 繊維製品 | D9: 0.0025763272 | E9: 0.0026072529 | F9: 0.00078554825 | G9: 0.20452188 | H9: 0.0020826967 | I9: 0.0016080674 | J9: 0.0004927929 | K9: 0.0015918303 | L9: 0.0028995643 | M9: 0.00087990776 | N9: 0.0021267935 | O9: 0.0012152223 | P9: 0.0013120535 | Q9: 0.0013303253 | R9: 0.0013556476 | S9: 0.0039730589 | T9: 0.0026140862 | U9: 0.0011814205 | V9: 0.00093114892 | W9: 0.0071464291 | X9: 0.0033873246 | Y9: 0.0003191082 | Z9: 0.00083469808 | AA9: 0.0027221134 | AB9: 0.004374021 | AC9: 0.0013509763 | AD9: 3.892222e-05 | AE9: 0.0010596289 | AF9: 0.0006987964 | AG9: 0.004492189 | AH9: 0.00043904892 | AI9: 0.0037156405 | AJ9: 0.022940646 | AK9: 0.0018333767 | AL9: 0.0045501575 | AM9: 0.020088614 | AN9: 0.00021568458 | AO9: 0.0026500727 | AP9: 0.012382729 | AQ9: 0.012654559 | AR9: 0 | AS9: 2.3707035e-05 | AT9: 0.0013093023 | AU9: 0.030376394 | AV9: 0.0064507265 | AW9: 0.0061450017 | AX9: 0.00098762884 | AY9: 0.00098762884 | AZ9: 0.0024551173 | BA9: 0.0020734891 | BB9: 0.0048306674 | BC9: 0.0051311332 | BD9: 0.049113261 | BE9: 0.23820132 | BF9: 0.052364432 | BG9: 0.051176656 | BH9: 0.0056494593 | BI9: 0.015302075 | BJ9: -0.0031120785 | BK9: 0.00097254509
A10: 5 | B10: 16 | C10: パルプ・紙・木製品 | D10: 0.051653945 | E10: 0.00047404598 | F10: 0.017673375 | G10: 0.0049090783 | H10: 0.29704563 | I10: 0.025984566 | J10: 0.00073918936 | K10: 0.0055332632 | L10: 0.013018898 | M10: 0.0010922993 | N10: 0.0034089753 | O10: 0.002663707 | P10: 0.0019099945 | Q10: 0.001087237 | R10: 0.0043708782 | S10: 0.0053207485 | T10: 0.0066061692 | U10: 0.0063393845 | V10: 0.001297363 | W10: 0.054188424 | X10: 0.043860969 | Y10: 0.0009502333 | Z10: 0.0036663321 | AA10: 0.004570338 | AB10: 0.007452387 | AC10: 0.0045835238 | AD10: 0.00041702378 | AE10: 0.003587052 | AF10: 0.011318877 | AG10: 0.0012646678 | AH10: 0.0074790236 | AI10: 0.0065535578 | AJ10: 0.018800801 | AK10: 0.004665104 | AL10: 0.0048088186 | AM10: 0.43235686 | AN10: 0.00060391683 | AO10: 0.013310345 | AP10: 0.0096060806 | AQ10: 0.0016778445 | AR10: 1.4495004e-05 | AS10: 0.00028617778 | AT10: 0.0024394155 | AU10: 0.046206055 | AV10: 0.001276901 | AW10: 0.013300781 | AX10: 0.00054835512 | AY10: 0.00054835512 | AZ10: 0.016385149 | BA10: 0.012266706 | BB10: 0.0053443372 | BC10: 0.013043281 | BD10: 0.023995518 | BE10: 0.026485149 | BF10: 0.024902236 | BG10: 0.0240986 | BH10: 0.024597731 | BI10: 0.024491906 | BJ10: -0.0091794277 | BK10: 0.0083622873
A11: 6 | B11: 20 | C11: 化学製品 | D11: 0.047387434 | E11: 0.0033183219 | F11: 0.012383336 | G11: 0.10315979 | H11: 0.024485759 | I11: 0.23291428 | J11: 0.036713071 | K11: 0.16394326 | L11: 0.06701782 | M11: 0.003610656 | N11: 0.011559988 | O11: 0.010019 | P11: 0.0046400224 | Q11: 0.0038028321 | R11: 0.0081821296 | S11: 0.0113766 | T11: 0.010194936 | U11: 0.01076179 | V11: 0.012468311 | W11: 0.030149906 | X11: 0.0046422804 | Y11: 0.00059921428 | Z11: 0.008811876 | AA11: 0.015529105 | AB11: 1.0344551e-05 | AC11: 2.6529746e-05 | AD11: 3.5744896e-05 | AE11: 0.00044658078 | AF11: 0.00087755828 | AG11: 0.0008822526 | AH11: 0.010332082 | AI11: 0.14337804 | AJ11: 0.002321185 | AK11: 0.0042303384 | AL11: 0.0086919883 | AM11: 0.0093345378 | AN11: 0.003623501 | AO11: 0.022693189 | AP11: 0.020951072 | AQ11: 0.0091132177 | AR11: 0 | AS11: 0 | AT11: 0 | AU11: -0.054462309 | AV11: 0.0050445361 | AW11: 0.02429509 | AX11: 0.01753336 | AY11: 0.01753336 | AZ11: 0.026122987 | BA11: 0.023889208 | BB11: 0.012019137 | BC11: 0.024194019 | BD11: 0.077730011 | BE11: 0.047277228 | BF11: 0.080179727 | BG11: 0.077658975 | BH11: 0.057127412 | BI11: 0.061480487 | BJ11: -0.025498161 | BK11: 0.0089487193
A12: 7 | B12: 21 | C12: 石油・石炭製品 | D12: 0.01093382 | E12: 0.021569092 | F12: 0.0034940836 | G12: 0.0033188135 | H12: 0.0023721835 | I12: 0.0053952915 | J12: 0.23654059 | K12: 0.00091542957 | L12: 0.030314289 | M12: 0.011347776 | N12: 0.0063702045 | O12: 0.0047329709 | P12: 0.0012197997 | Q12: 0.00090575337 | R12: 0.00086838639 | S12: 0.0013158669 | T12: 0.0007170065 | U12: 0.00026253788 | V12: 0.0032817322 | W12: 0.0021282287 | X12: 0.01290774 | Y12: 0.0047511665 | Z12: 0.012235195 | AA12: 0.012324846 | AB12: 0.0014732365 | AC12: 0.00055508392 | AD12: 0.00032567572 | AE12: 0.13099863 | AF12: 0.00081052257 | AG12: 0.0072182861 | AH12: 0.0031736097 | AI12: 0.0024896015 | AJ12: 0.0033820702 | AK12: 0.0020220051 | AL12: 0.0044541763 | AM12: 0 | AN12: 0.0094901216 | AO12: 0.0092767339 | AP12: 0.0016056879 | AQ12: 0.024076325 | AR12: 0 | AS12: 0 | AT12: 0 | AU12: -0.0068077886 | AV12: 0.011717915 | AW12: 0.015380554 | AX12: 8.8444374e-06 | AY12: 8.8444374e-06 | AZ12: 1.0879397e-05 | BA12: 1.0350195e-05 | BB12: 0.0073848288 | BC12: 0.01155314 | BD12: 0.017192563 | BE12: 0.0094059406 | BF12: 0.035309799 | BG12: 0.01871138 | BH12: 0.043792075 | BI12: 0.038474499 | BJ12: -0.016197229 | BK12: 0.00054581681
A13: 8 | B13: 22 | C13: プラスチック・ゴム製品 | D13: 0.015183344 | E13: 0.0035553449 | F13: 0.030471387 | G13: 0.010855286 | H13: 0.015720742 | I13: 0.052277219 | J13: 0.00073918936 | K13: 0.21850795 | L13: 0.003409538 | M13: 0.00042478306 | N13: 0.0076116821 | O13: 0.003156568 | P13: 0.012464508 | Q13: 0.019325513 | R13: 0.042174633 | S13: 0.013494398 | T13: 0.026633804 | U13: 0.046290408 | V13: 0.047590794 | W13: 0.046815216 | X13: 0.01423222 | Y13: 0 | Z13: 0.039452692 | AA13: 0.020541409 | AB13: 0.0059800126 | AC13: 0.0025203259 | AD13: 0.00060528024 | AE13: 0.0046482816 | AF13: 0.0025737647 | AG13: 0.001632802 | AH13: 0.0044436612 | AI13: 0.0022114383 | AJ13: 0.0077931194 | AK13: 0.012255099 | AL13: 0.00257685 | AM13: 0.046113477 | AN13: 0.002056193 | AO13: 0.014886805 | AP13: 0.0025172138 | AQ13: 0.0028378186 | AR13: 2.4848579e-05 | AS13: 0 | AT13: -4.07248e-06 | AU13: 0.030521241 | AV13: 0.0012525748 | AW13: 0.014777036 | AX13: 0.022691141 | AY13: 0.022691141 | AZ13: 0.036727032 | BA13: 0.033076923 | BB13: 0.013031083 | BC13: 0.019333986 | BD13: 0.022981562 | BE13: 0.055940594 | BF13: 0.024204867 | BG13: 0.023398921 | BH13: 0.03721071 | BI13: 0.034282353 | BJ13: -0.0030883764 | BK13: 0.013222054
A14: 9 | B14: 25 | C14: 窯業・土石製品 | D14: 0.0032388114 | E14: 0 | F14: 0.0023581049 | G14: 0.00048399364 | H14: 0.0013991862 | I14: 0.01302234 | J14: 0.025748429 | K14: 0.0030412604 | L14: 0.089529513 | M14: 0.0056132047 | N14: 0.021593569 | O14: 0.0059218571 | P14: 0.0085215139 | Q14: 0.0041774544 | R14: 0.045706071 | S14: 0.048273382 | T14: 0.007700351 | U14: 0.0024941099 | V14: 0.0025691761 | W14: 0.0056810913 | X14: 0.052769747 | Y14: 0.0001063694 | Z14: 0.0052934651 | AA14: 0.00050223495 | AB14: 0.00021033921 | AC14: 1.2244498e-05 | AD14: 7.3872785e-05 | AE14: 2.4009719e-05 | AF14: 8.1255396e-06 | AG14: 0.00022373672 | AH14: 0.0018503861 | AI14: 0.00081735934 | AJ14: 0.00047061826 | AK14: 0.0012835937 | AL14: 0.0010899555 | AM14: 0.0053770379 | AN14: 0.0027607627 | AO14: 0.0092083471 | AP14: 0.0010096902 | AQ14: 0.00029080778 | AR14: 0 | AS14: 0 | AT14: 0 | AU14: 0.13783185 | AV14: -0.00059317672 | AW14: 0.0083684718 | AX14: 0.022674189 | AY14: 0.022674189 | AZ14: 0.016016545 | BA14: 0.017747901 | BB14: 0.0061950386 | BC14: 0.010704092 | BD14: 0.010508189 | BE14: 0.0031353135 | BF14: 0.010822454 | BG14: 0.010466489 | BH14: 0.01534337 | BI14: 0.01430938 | BJ14: 4.0168729e-05 | BK14: 0.0092299995
A15: 10 | B15: 26 | C15: 鉄鋼 | D15: 3.9635804e-05 | E15: 0.0021332069 | F15: 0 | G15: 0.00020742585 | H15: 0.012118239 | I15: 0 | J15: 0 | K15: 0.0016274303 | L15: 0.0038976556 | M15: 0.35724255 | N15: 0.0014653506 | O15: 0.20884892 | P15: 0.092205924 | Q15: 0.083888746 | R15: 0.016127865 | S15: 0.0070598568 | T15: 0.041922474 | U15: 0.0093449906 | V15: 0.053064133 | W15: 0.0062218707 | X15: 0.01920804 | Y15: 0 | Z15: 3.1697396e-05 | AA15: 0 | AB15: 0 | AC15: 0 | AD15: 0 | AE15: 0.00013285378 | AF15: 0 | AG15: 1.9041423e-05 | AH15: 0 | AI15: 3.2629115e-06 | AJ15: 7.9765808e-06 | AK15: 0.00018977864 | AL15: 3.2535985e-05 | AM15: 4.3016303e-05 | AN15: 0.0025019412 | AO15: 0.014280738 | AP15: 0 | AQ15: -0.00011167019 | AR15: 0 | AS15: -0.00080434584 | AT15: -0.0011601477 | AU15: 0.034618329 | AV15: -0.00055263303 | AW15: 0.013185493 | AX15: 0.0042814447 | AY15: 0.0042814447 | AZ15: 0.004010094 | BA15: 0.0040806602 | BB15: 0.0011621949 | BC15: 0.010918251 | BD15: 0.008775872 | BE15: 0 | BF15: 0.0090128263 | BG15: 0.008714188 | BH15: 0.038521014 | BI15: 0.03220141 | BJ15: -0.022381591 | BK15: 0.0022162166
A16: 11 | B16: 27 | C16: 非鉄金属 | D16: 0 | E16: 0 | F16: 0.0014703477 | G16: 0 | H16: 0.0029672397 | I16: 0.0043733422 | J16: 0 | K16: 0.0025835457 | L16: 0.012756626 | M16: 0.0012136659 | N16: 0.52933754 | O16: 0.039421359 | P16: 0.031263774 | Q16: 0.019933234 | R16: 0.039574298 | S16: 0.057864731 | T16: 0.057995369 | U16: 0.045145199 | V16: 0.038625647 | W16: 0.016293161 | X16: 0.0085523566 | Y16: 0.00093250507 | Z16: 0.00021131597 | AA16: 0 | AB16: 1.2930689e-05 | AC16: 0 | AD16: 0 | AE16: 1.6006479e-06 | AF16: 9.953786e-05 | AG16: 0.00013170318 | AH16: 0.00010026723 | AI16: 0.0014854405 | AJ16: 0.00021536768 | AK16: 0.00037380641 | AL16: 0.00040344621 | AM16: 0.00094635867 | AN16: 0.0021856038 | AO16: 0.013256416 | AP16: 0.00014023475 | AQ16: 0.00063535683 | AR16: 0 | AS16: 0 | AT16: -0.0011296041 | AU16: 0.028203696 | AV16: -9.3588353e-05 | AW16: 0.01247641 | AX16: 0.012461075 | AY16: 0.012461075 | AZ16: 0.018117305 | BA16: 0.016646372 | BB16: 0.0061020375 | BC16: 0.013514794 | BD16: 0.056188609 | BE16: 0.014191419 | BF16: 0.057872761 | BG16: 0.055941767 | BH16: 0.023536631 | BI16: 0.030407125 | BJ16: -0.012333796 | BK16: 0.0066080347
A17: 12 | B17: 28 | C17: 金属製品 | D17: 0.002330019 | E17: 0.0090068737 | F17: 0.013542677 | G17: 0.001382839 | H17: 0.014096399 | I17: 0.017568512 | J17: 0.00012319823 | K17: 0.0035345753 | L17: 0.0084145648 | M17: 0.0069785788 | N17: 0.0046504528 | O17: 0.066340601 | P17: 0.036286479 | Q17: 0.031588149 | R17: 0.037480522 | S17: 0.026042073 | T17: 0.028822167 | U17: 0.031524915 | V17: 0.012244041 | W17: 0.012280926 | X17: 0.080855764 | Y17: 0.00077295097 | Z17: 0.0007396059 | AA17: 0.00015067048 | AB17: 0.0026404467 | AC17: 0.00011428198 | AD17: 0.00030502311 | AE17: 0.00096359006 | AF17: 0.00047737545 | AG17: 0.0028070231 | AH17: 0.00021876486 | AI17: 0.000368709 | AJ17: 0.0023291616 | AK17: 0.0011904296 | AL17: 0.0024336917 | AM17: 0.00038714673 | AN17: 0.0030195842 | AO17: 0.014668801 | AP17: 0.0032464345 | AQ17: 0.0011043716 | AR17: 3.1060724e-06 | AS17: 0.00082635951 | AT17: 0.003665741 | AU17: 0.083100544 | AV17: 0.0010010913 | AW17: 0.014429072 | AX17: 0.007157361 | AY17: 0.007157361 | AZ17: 0.04961031 | BA17: 0.038570193 | BB17: 0.01490579 | BC17: 0.020440578 | BD17: 0.016745735 | BE17: 0.012128713 | BF17: 0.017328284 | BG17: 0.016753519 | BH17: 0.0294019 | BI17: 0.026720207 | BJ17: 0.0059443481 | BK17: 0.017873029
... A43: 38 | B43: 70 | C43: 内生部門計 | D43: 0.51824096 | E43: 0.59706091 | F43: 0.67026101 | G43: 0.58494088 | H43: 0.60974766 | I43: 0.59551094 | J43: 0.53123075 | K43: 0.577692 | L43: 0.5447684 | M43: 0.59961163 | N43: 0.81167192 | O43: 0.49597622 | P43: 0.51631012 | Q43: 0.52631097 | R43: 0.59469995 | S43: 0.66636806 | T43: 0.62458735 | U43: 0.66778094 | V43: 0.71745876 | W43: 0.55508391 | X43: 0.52193929 | Y43: 0.47864457 | Z43: 0.56457288 | AA43: 0.36454221 | AB43: 0.32391376 | AC43: 0.37677545 | AD43: 0.16282197 | AE43: 0.56884947 | AF43: 0.49687878 | AG43: 0.27527392 | AH43: 0.31894094 | AI43: 0.40082829 | AJ43: 0.39430632 | AK43: 0.40170962 | AL43: 0.4858745 | AM43: 1 | AN43: 0.35372272 | AO43: 0.4609623 | AP43: 1 | AQ43: 1 | AR43: 1 | AS43: 1 | AT43: 1 | AU43: 1 | AV43: 1 | AW43: 1 | AX43: 1 | AY43: 1 | AZ43: 1 | BA43: 1 | BB43: 1 | BC43: 1 | BD43: 1 | BE43: 1 | BF43: 1 | BG43: 1 | BH43: 1 | BI43: 1 | BJ43: 1 | BK43: 1
A44: 39 | B44: 71 | C44: 家計外消費支出（行） | D44: 0.003165202 | E44: 0.010903058 | F44: 0.0059573176 | G44: 0.0087810274 | H44: 0.010333071 | I44: 0.0087767416 | J44: 0.0057903166 | K44: 0.013970472 | L44: 0.011605543 | M44: 0.003094848 | N44: 0.0064923171 | O44: 0.012242518 | P44: 0.010469093 | Q44: 0.009691894 | R44: 0.01150612 | S44: 0.0097043198 | T44: 0.011950108 | U44: 0.01443732 | V44: 0.005836714 | W44: 0.011309849 | X44: 0.012069929 | Y44: 0.01220057 | Z44: 0.0083152834 | AA44: 0.017347195 | AB44: 0.013665152 | AC44: 0.024827761 | AD44: 0.0012343904 | AE44: 0.0062233192 | AF44: 0.0063480778 | AG44: 0.0083385565 | AH44: 0.0031888017 | AI44: 0.0082983998 | AJ44: 0.035033143 | AK44: 0.0090553164 | AL44: 0.015093443 | AM44: 0 | AN44: 0.0019986771 | AO44: 0.0095901566
A45: 40 | B45: 91 | C45: 雇用者所得 | D45: 0.20088275 | E45: 0.26736193 | F45: 0.13906686 | G45: 0.28984305 | H45: 0.18140369 | I45: 0.10767289 | J45: 0.086854749 | K45: 0.23211734 | L45: 0.22848276 | M45: 0.16542266 | N45: 0.14846851 | O45: 0.29799658 | P45: 0.26946981 | Q45: 0.27201072 | R45: 0.28117869 | S45: 0.26468655 | T45: 0.2202629 | U45: 0.17244212 | V45: 0.18345053 | W45: 0.28237989 | X45: 0.3447353 | Y45: 0.1260832 | Z45: 0.11851656 | AA45: 0.4540003 | AB45: 0.43822019 | AC45: 0.30032285 | AD45: 0.042218694 | AE45: 0.26558911 | AF45: 0.17241786 | AG45: 0.34749645 | AH45: 0.49119699 | AI45: 0.52882823 | AJ45: 0.53009963 | AK45: 0.36968879 | AL45: 0.31666623 | AM45: 0 | AN45: 0.0074195497 | AO45: 0.29031846
A46: 41 | B46: 92 | C46: 営業余剰 | D46: 0.12903436 | E46: -0.036501541 | F46: 0.092595405 | G46: -0.0076056143 | H46: 0.097573136 | I46: 0.053847715 | J46: 0.20980658 | K46: 0.060413266 | L46: 0.075374102 | M46: 0.15716973 | N46: -0.0046097487 | O46: 0.065907937 | P46: 0.093203631 | Q46: 0.067441996 | R46: 0.0066769265 | S46: -0.084080238 | T46: -0.0095526178 | U46: -0.013167633 | V46: -0.012678387 | W46: 0.019229651 | X46: 0.025806679 | Y46: -0.17882114 | Z46: 0.10183317 | AA46: 0.042910954 | AB46: 0.069911925 | AC46: 0.21762555 | AD46: 0.37200507 | AE46: 0.041000597 | AF46: 0.13749226 | AG46: -0.0056584762 | AH46: 0.010534136 | AI46: 0.0079655828 | AJ46: -0.015155503 | AK46: 0.064589147 | AL46: -0.0056840365 | AM46: 0 | AN46: 0.57177983 | AO46: 0.069046868
A47: 42 | B47: 93 | C47: 資本減耗引当 | D47: 0.14701203 | E47: 0.10903058 | F47: 0.062776694 | G47: 0.1030215 | H47: 0.06135512 | I47: 0.22286011 | J47: 0.11987187 | K47: 0.091726042 | L47: 0.10648249 | M47: 0.039322774 | N47: 0.028879617 | O47: 0.08773679 | P47: 0.10449617 | Q47: 0.11992241 | R47: 0.15163956 | S47: 0.15937742 | T47: 0.18033087 | U47: 0.20591797 | V47: 0.10885074 | W47: 0.11944247 | X47: 0.051944257 | Y47: 0.5142535 | Z47: 0.20334936 | AA47: 0.078087489 | AB47: 0.097188782 | AC47: 0.075913848 | AD47: 0.3499608 | AE47: 0.085021617 | AF47: 0.15748718 | AG47: 0.37277077 | AH47: 0.17020058 | AI47: 0.056287671 | AJ47: 0.043408552 | AK47: 0.10217107 | AL47: 0.13918894 | AM47: 0 | AN47: 0.035156587 | AO47: 0.14646187
A48: 43 | B48: 94 | C48: 間接税（関税・輸入品商品税を除く。） | D48: 0.027453456 | E48: 0.052145058 | F48: 0.030823278 | G48: 0.021019152 | H48: 0.03958732 | I48: 0.011331615 | J48: 0.046445731 | K48: 0.024080883 | L48: 0.033286707 | M48: 0.03537836 | N48: 0.0090973848 | O48: 0.040147482 | P48: 0.0060545801 | Q48: 0.0046236711 | R48: -0.045696422 | S48: -0.016049758 | T48: -0.027578609 | U48: -0.047408457 | V48: -0.0029126792 | W48: 0.012554223 | X48: 0.048364201 | Y48: 0.047837865 | Z48: 0.038089704 | AA48: 0.043111848 | AB48: 0.057820007 | AC48: 0.017158623 | AD48: 0.071893312 | AE48: 0.035571199 | AF48: 0.02937992 | AG48: 0.0017787863 | AH48: 0.0077418453 | AI48: 0.0098841748 | AJ48: 0.031451658 | AK48: 0.05281482 | AL48: 0.048860915 | AM48: 0 | AN48: 0.032884709 | AO48: 0.026729557
A49: 44 | B49: 95 | C49: （控除）経常補助金 | D49: -0.025788752 | E49: 0 | F49: -0.0014805686 | G49: 0 | H49: 0 | I49: 0 | J49: 0 | K49: 0 | L49: 0 | M49: 0 | N49: 0 | O49: -7.524596e-06 | P49: -3.4168059e-06 | Q49: -1.6649878e-06 | R49: -4.8243689e-06 | S49: -6.3645317e-06 | T49: 0 | U49: -2.2632576e-06 | V49: -5.6777373e-06 | W49: 0 | X49: -0.0048596535 | Y49: -0.00019855621 | Z49: -0.034676951 | AA49: 0 | AB49: -0.00071980835 | AC49: -0.012624078 | AD49: -0.00013424194 | AE49: -0.002255313 | AF49: -4.0627698e-06 | AG49: 0 | AH49: -0.0018032909 | AI49: -0.01209235 | AJ49: -0.019143794 | AK49: -2.8754339e-05 | AL49: 0 | AM49: 0 | AN49: -0.0029620683 | AO49: -0.0031092124
A50: 45 | B50: 96 | C50: 粗付加価値部門計 | D50: 0.48175904 | E50: 0.40293909 | F50: 0.32973899 | G50: 0.41505912 | H50: 0.39025234 | I50: 0.40448906 | J50: 0.46876925 | K50: 0.422308 | L50: 0.4552316 | M50: 0.40038837 | N50: 0.18832808 | O50: 0.50402378 | P50: 0.48368988 | Q50: 0.47368903 | R50: 0.40530005 | S50: 0.33363194 | T50: 0.37541265 | U50: 0.33221906 | V50: 0.28254124 | W50: 0.44491609 | X50: 0.47806071 | Y50: 0.52135543 | Z50: 0.43542712 | AA50: 0.63545779 | AB50: 0.67608624 | AC50: 0.62322455 | AD50: 0.83717803 | AE50: 0.43115053 | AF50: 0.50312122 | AG50: 0.72472608 | AH50: 0.68105906 | AI50: 0.59917171 | AJ50: 0.60569368 | AK50: 0.59829038 | AL50: 0.5141255 | AM50: 0 | AN50: 0.64627728 | AO50: 0.5390377
A51: 46 | B51: 97 | C51: 県内生産額 | D51: 1 | E51: 1 | F51: 1 | G51: 1 | H51: 1 | I51: 1 | J51: 1 | K51: 1 | L51: 1 | M51: 1 | N51: 1 | O51: 1 | P51: 1 | Q51: 1 | R51: 1 | S51: 1 | T51: 1 | U51: 1 | V51: 1 | W51: 1 | X51: 1 | Y51: 1 | Z51: 1 | AA51: 1 | AB51: 1 | AC51: 1 | AD51: 1 | AE51: 1 | AF51: 1 | AG51: 1 | AH51: 1 | AI51: 1 | AJ51: 1 | AK51: 1 | AL51: 1 | AM51: 1 | AN51: 1 | AO51: 1

Sheet 逆行列係数表（閉鎖型）
A1: 令和２年（2020年）長野県産業連関表
A2: 第３表 逆行列係数表 (I-A)-1型
D3: 1 | E3: 2 | F3: 3 | G3: 4 | H3: 5 | I3: 6 | J3: 7 | K3: 8 | L3: 9 | M3: 10 | N3: 11 | O3: 12 | P3: 13 | Q3: 14 | R3: 15 | S3: 16 | T3: 17 | U3: 18 | V3: 19 | W3: 20 | X3: 21 | Y3: 22 | Z3: 23 | AA3: 24 | AB3: 25 | AC3: 26 | AD3: 27 | AE3: 28 | AF3: 29 | AG3: 30 | AH3: 31 | AI3: 32 | AJ3: 33 | AK3: 34 | AL3: 35 | AM3: 36 | AN3: 37
D4: 01 | E4: 06 | F4: 11 | G4: 15 | H4: 16 | I4: 20 | J4: 21 | K4: 22 | L4: 25 | M4: 26 | N4: 27 | O4: 28 | P4: 29 | Q4: 30 | R4: 31 | S4: 32 | T4: 33 | U4: 34 | V4: 35 | W4: 39 | X4: 41 | Y4: 46 | Z4: 47 | AA4: 48 | AB4: 51 | AC4: 53 | AD4: 55 | AE4: 57 | AF4: 59 | AG4: 61 | AH4: 63 | AI4: 64 | AJ4: 65 | AK4: 66 | AL4: 67 | AM4: 68 | AN4: 69
C5: 統合大分類（37部門） | D5: 農業 | E5: 鉱業 | F5: 飲食料品 | G5: 繊維製品 | H5: パルプ・紙・木製品 | I5: 化学製品 | J5: 石油・石炭製品 | K5: プラスチック・ゴム製品 | L5: 窯業・土石製品 | M5: 鉄鋼 | N5: 非鉄金属 | O5: 金属製品 | P5: はん用機械 | Q5: 生産用機械 | R5: 業務用機械 | S5: 電子部品 | T5: 電気機械 | U5: 情報通信機器 | V5: 輸送機械 | W5: その他の製造工業製品 | X5: 建設 | Y5: 電気・ガス・熱供給 | Z5: 水道 | AA5: 廃棄物処理 | AB5: 商業 | AC5: 金融・保険 | AD5: 不動産 | AE5: 運輸・郵便 | AF5: 情報通信 | AG5: 公務 | AH5: 教育・研究 | AI5: 医療・福祉 | AJ5: 他に分類されない会員制団体 | AK5: 対事業所サービス | AL5: 対個人サービス | AM5: 事務用品 | AN5: 分類不明 | AO5: 行和 | AP5: 感応度係数
A6: 1 | B6: 01 | C6: 農林漁業 | D6: 1.1411766 | E6: 0.00067810751 | F6: 0.22424798 | G6: 0.018266378 | H6: 0.041466169 | I6: 0.0092781659 | J6: 0.00089384325 | K6: 0.0035697174 | L6: 0.0023165914 | M6: 0.0006164527 | N6: 0.0023419441 | O6: 0.00071047813 | P6: 0.00071483804 | Q6: 0.00067422748 | R6: 0.001242389 | S6: 0.001446957 | T6: 0.0013475996 | U6: 0.0014663149 | V6: 0.0011274122 | W6: 0.010871276 | X6: 0.0037517658 | Y6: 0.00055785856 | Z6: 0.0011857404 | AA6: 0.00087273069 | AB6: 0.0010509322 | AC6: 0.00086095957 | AD6: 0.00022378477 | AE6: 0.0008089891 | AF6: 0.001856959 | AG6: 0.000753265 | AH6: 0.0048924748 | AI6: 0.0074582785 | AJ6: 0.0050013234 | AK6: 0.00094904384 | AL6: 0.045695971 | AM6: 0.020340363 | AN6: 0.0014805462 | AO6: 1.5621944 | AP6: 0.73996714
A7: 2 | B7: 06 | C7: 鉱業 | D7: 0.0044981519 | E7: 1.0072726 | F7: 0.0043611985 | G7: 0.0041757893 | H7: 0.0056639588 | I7: 0.0091175618 | J7: 0.068194514 | K7: 0.0048922909 | L7: 0.036896195 | M7: 0.008441782 | N7: 0.06032327 | O7: 0.006955229 | P7: 0.0058519781 | Q7: 0.0048190268 | R7: 0.0085585027 | S7: 0.01163779 | T7: 0.0086392292 | U7: 0.0082768091 | V7: 0.0083304404 | W7: 0.0058348443 | X7: 0.0080768955 | Y7: 0.051257399 | Z7: 0.0059727111 | AA7: 0.0059973574 | AB7: 0.0026770904 | AC7: 0.0014450682 | AD7: 0.00054202788 | AE7: 0.011095325 | AF7: 0.0018337201 | AG7: 0.00222109 | AH7: 0.0023379565 | AI7: 0.0031377581 | AJ7: 0.0020161436 | AK7: 0.0020035045 | AL7: 0.0039551794 | AM7: 0.0057521028 | AN7: 0.0025194721 | AO7: 1.3955819 | AP7: 0.66104754
A8: 3 | B8: 11 | C8: 飲食料品 | D8: 0.064325876 | E8: 0.00064987863 | F8: 1.3070332 | G8: 0.0093972367 | H8: 0.0055491628 | I8: 0.021909073 | J8: 0.0015448232 | K8: 0.0050043624 | L8: 0.0028425271 | M8: 0.00059597456 | N8: 0.0016729949 | O8: 0.00070280644 | P8: 0.00070115893 | Q8: 0.00067356074 | R8: 0.0011405486 | S8: 0.001275105 | T8: 0.0011364931 | U8: 0.0013182133 | V8: 0.0013063047 | W8: 0.0042482473 | X8: 0.0011895787 | Y8: 0.0004842304 | Z8: 0.0011168509 | AA8: 0.00084842206 | AB8: 0.00075070952 | AC8: 0.00060785928 | AD8: 0.0002258268 | AE8: 0.00073650359 | AF8: 0.0023746395 | AG8: 0.0013795619 | AH8: 0.010970133 | AI8: 0.017593161 | AJ8: 0.0035479087 | AK8: 0.0010094006 | AL8: 0.14343085 | AM8: 0.0038834651 | AN8: 0.0060755837 | AO8: 1.6292522 | AP8: 0.77173052
A9: 4 | B9: 15 | C9: 繊維製品 | D9: 0.0059461318 | E9: 0.0055930904 | F9: 0.0044451981 | G9: 1.2597578 | H9: 0.00605694 | I9: 0.0050389918 | J9: 0.0026119421 | K9: 0.0048919235 | L9: 0.0062804764 | M9: 0.0033096104 | N9: 0.00942085 | O9: 0.0036453239 | P9: 0.0041678279 | Q9: 0.0041703081 | R9: 0.0055541486 | S9: 0.010240984 | T9: 0.0078120289 | U9: 0.0066872232 | V9: 0.0050505096 | W9: 0.012466937 | X9: 0.0067812667 | Y9: 0.002347507 | Z9: 0.0039175503 | AA9: 0.0050144475 | AB9: 0.0067608991 | AC9: 0.0034625374 | AD9: 0.00058363655 | AE9: 0.0036267316 | AF9: 0.0030223537 | AG9: 0.0069308697 | AH9: 0.0022674617 | AI9: 0.0067791688 | AJ9: 0.030838249 | AK9: 0.0042679386 | AL9: 0.0080116597 | AM9: 0.032147879 | AN9: 0.0019525004 | AO9: 1.5018609 | AP9: 0.71138887
A10: 5 | B10: 16 | C10: パルプ・紙・木製品 | D10: 0.09530711 | E10: 0.010805825 | F10: 0.059742533 | G10: 0.026524289 | H10: 1.4366309 | I10: 0.059171032 | J10: 0.010351022 | K10: 0.027549389 | L10: 0.032574365 | M10: 0.0096561021 | N10: 0.030957137 | O10: 0.012000439 | P10: 0.011453867 | Q10: 0.010335585 | R10: 0.020452631 | S10: 0.025425179 | T10: 0.024274358 | U10: 0.025994491 | V10: 0.01534108 | W10: 0.095781654 | X10: 0.072543111 | Y10: 0.0094980452 | Z10: 0.0194773 | AA10: 0.01530621 | AB10: 0.017777196 | AC10: 0.016631676 | AD10: 0.0037396796 | AE10: 0.015268139 | AF10: 0.030003079 | AG10: 0.0094014583 | AH10: 0.021286596 | AI10: 0.024839926 | AJ10: 0.040327465 | AK10: 0.015790664 | AL10: 0.022805039 | AM10: 0.64253911 | AN10: 0.0076366424 | AO10: 3.0252003 | AP10: 1.4329515
A11: 6 | B11: 20 | C11: 化学製品 | D11: 0.088571924 | E11: 0.01761555 | F11: 0.057136223 | G11: 0.18447503 | H11: 0.063156513 | I11: 1.3347855 | J11: 0.073322682 | K11: 0.28511586 | L11: 0.10992282 | M11: 0.015457232 | N11: 0.057829391 | O11: 0.025101362 | P11: 0.021810282 | Q11: 0.022590665 | R11: 0.044960752 | S11: 0.047300872 | T11: 0.042914162 | U11: 0.051199737 | V11: 0.059550965 | W11: 0.071364359 | X11: 0.028228264 | Y11: 0.0085039258 | Z11: 0.034995039 | AA11: 0.033430551 | AB11: 0.0079437179 | AC11: 0.0075377052 | AD11: 0.0019057008 | AE11: 0.019476847 | AF11: 0.011397634 | AG11: 0.0089716563 | AH11: 0.022572768 | AI11: 0.20045594 | AJ11: 0.018418363 | AK11: 0.018719861 | AL11: 0.02710054 | AM11: 0.072152253 | AN11: 0.011413055 | AO11: 3.2074057 | AP11: 1.519257
A12: 7 | B12: 21 | C12: 石油・石炭製品 | D12: 0.047694719 | E12: 0.11091263 | F12: 0.032320839 | G12: 0.023971605 | H12: 0.02821397 | I12: 0.025978415 | J12: 1.3417885 | K12: 0.016300541 | L12: 0.073556541 | M12: 0.044223144 | N12: 0.050460589 | O12: 0.029015535 | P12: 0.019671468 | Q12: 0.018068464 | R12: 0.023427932 | S12: 0.023405098 | T12: 0.020705914 | U12: 0.02002818 | V12: 0.026070892 | W12: 0.032854989 | X12: 0.040841782 | Y12: 0.021253592 | Z12: 0.03357034 | AA12: 0.039022611 | AB12: 0.018767164 | AC12: 0.013414338 | AD12: 0.0032692943 | AE12: 0.1962152 | AF12: 0.013921118 | AG12: 0.021952289 | AH12: 0.016673026 | AI12: 0.015541336 | AJ12: 0.019998956 | AK12: 0.0128967 | AL12: 0.027392196 | AM12: 0.036242246 | AN12: 0.029240696 | AO12: 2.5688829 | AP12: 1.2168069
A13: 8 | B13: 22 | C13: プラスチック・ゴム製品 | D13: 0.038481509 | E13: 0.015768383 | F13: 0.067912957 | G13: 0.038762061 | H13: 0.041258078 | I13: 0.099245057 | J13: 0.012310063 | K13: 1.305814 | L13: 0.020711712 | M13: 0.0079447401 | N13: 0.040183939 | O13: 0.012468607 | P13: 0.02804317 | Q13: 0.039390648 | R13: 0.074856334 | S13: 0.039323823 | T13: 0.054992559 | U13: 0.082889039 | V13: 0.10912633 | W13: 0.079846028 | X13: 0.030492987 | Y13: 0.0098566178 | Z13: 0.068107127 | AA13: 0.035288065 | AB13: 0.014518186 | AC13: 0.011911026 | AD13: 0.0030812192 | AE13: 0.01856252 | AF13: 0.015225754 | AG13: 0.010199509 | AH13: 0.015550954 | AI13: 0.023893541 | AJ13: 0.021284743 | AK13: 0.029653904 | AL13: 0.019466185 | AM13: 0.097841675 | AN13: 0.0089134457 | AO13: 2.6431765 | AP13: 1.2519976
A14: 9 | B14: 25 | C14: 窯業・土石製品 | D14: 0.0084944717 | E14: 0.005444977 | F14: 0.0079550758 | G14: 0.0058321533 | H14: 0.0064196124 | I14: 0.022410615 | J14: 0.040694773 | K14: 0.010839716 | L14: 1.1048517 | M14: 0.012911893 | N14: 0.056033172 | O14: 0.013959672 | P14: 0.017806627 | Q14: 0.01300258 | R14: 0.07163509 | S14: 0.085194354 | T14: 0.033514216 | U14: 0.035241915 | V14: 0.0162173 | W14: 0.013729361 | X14: 0.063205337 | Y14: 0.0038423604 | Z14: 0.013136921 | AA14: 0.0036732709 | AB14: 0.0023300828 | AC14: 0.0021122886 | AD14: 0.0013889134 | AE14: 0.0086165666 | AF14: 0.0028065046 | AG14: 0.0029552808 | AH14: 0.0047139499 | AI14: 0.0064924428 | AJ14: 0.0031426625 | AK14: 0.005680026 | AL14: 0.0045308428 | AM14: 0.016875188 | AN14: 0.0059701681 | AO14: 1.7336621 | AP14: 0.82118652
A15: 10 | B15: 26 | C15: 鉄鋼 | D15: 0.0068114055 | E15: 0.011726105 | F15: 0.011417182 | G15: 0.0059473324 | H15: 0.037838061 | I15: 0.013486925 | J15: 0.0044753786 | K15: 0.011064023 | L15: 0.015794147 | M15: 1.5633899 | N15: 0.015903319 | O15: 0.35267589 | P15: 0.18974301 | Q15: 0.18101241 | R15: 0.054920992 | S15: 0.03740963 | T15: 0.096100803 | U15: 0.043518659 | V15: 0.14797459 | W15: 0.023282218 | X15: 0.066082698 | Y15: 0.0061535189 | Z15: 0.010970734 | AA15: 0.0034641916 | AB15: 0.0040577169 | AC15: 0.0037194954 | AD15: 0.0017702183 | AE15: 0.0069151969 | AF15: 0.0052368149 | AG15: 0.0050013889 | AH15: 0.0039702491 | AI15: 0.0049399592 | AJ15: 0.005165926 | AK15: 0.0141228 | AL15: 0.0050363039 | AM15: 0.024308029 | AN15: 0.0080346782 | AO15: 3.0034419 | AP15: 1.4226451
A16: 11 | B16: 27 | C16: 非鉄金属 | D16: 0.0050697204 | E16: 0.0054021673 | F16: 0.010627442 | G16: 0.0063428919 | H16: 0.015301913 | I16: 0.01964574 | J16: 0.0047602215 | K16: 0.014411431 | L16: 0.03605837 | M16: 0.0087691908 | N16: 2.1364367 | O16: 0.094479623 | P16: 0.090651471 | Q16: 0.068609134 | R16: 0.12921182 | S16: 0.19090282 | T16: 0.18149127 | U16: 0.16832027 | V16: 0.15126743 | W16: 0.049270873 | X16: 0.034062837 | Y16: 0.0075203577 | Z16: 0.0088916363 | AA16: 0.0036746734 | AB16: 0.0035127434 | AC16: 0.0040906534 | AD16: 0.0012884693 | AE16: 0.0063040847 | AF16: 0.0059674829 | AG16: 0.0051019186 | AH16: 0.0046830488 | AI16: 0.0096603319 | AJ16: 0.0057035579 | AK16: 0.015497706 | AL16: 0.0052261925 | AM16: 0.026584009 | AN16: 0.0077005206 | AO16: 3.5425007 | AP16: 1.677982
A17: 12 | B17: 28 | C17: 金属製品 | D17: 0.0093203193 | E17: 0.013623178 | F17: 0.024219181 | G17: 0.0086582217 | H17: 0.026295634 | I17: 0.029428724 | J17: 0.0052564733 | K17: 0.01357687 | L17: 0.016166761 | M17: 0.01497371 | N17: 0.018261656 | O17: 1.0772301 | P17: 0.051561142 | Q17: 0.048048533 | R17: 0.05577533 | S17: 0.047429477 | T17: 0.048492616 | U17: 0.054200139 | V17: 0.03110958 | W17: 0.021545514 | X17: 0.092523169 | Y17: 0.0058419036 | Z17: 0.0099515613 | AA17: 0.0032816228 | AB17: 0.0052772941 | AC17: 0.0027621538 | AD17: 0.0021498175 | AE17: 0.0057281678 | AF17: 0.0042930809 | AG17: 0.0059237458 | AH17: 0.0036485462 | AI17: 0.0073564388 | AJ17: 0.0060560818 | AK17: 0.0068325475 | AL17: 0.0080315015 | AM17: 0.020189983 | AN17: 0.0066085963 | AO17: 1.8116294 | AP17: 0.85811742
... A42: 37 | B42: 69 | C42: 分類不明 | D42: 0.012346739 | E42: 0.010649271 | F42: 0.0090879181 | G42: 0.0071262113 | H42: 0.0078634853 | I42: 0.0052027893 | J42: 0.029074905 | K42: 0.0052755046 | L42: 0.017550324 | M42: 0.021186885 | N42: 0.014378225 | O42: 0.011758493 | P42: 0.01427312 | Q42: 0.012096479 | R42: 0.0082715346 | S42: 0.0066311572 | T42: 0.007326593 | U42: 0.0065320645 | V42: 0.0075366071 | W42: 0.0063545956 | X42: 0.019472293 | Y42: 0.0069826789 | Z42: 0.012891051 | AA42: 0.010835197 | AB42: 0.0068257441 | AC42: 0.013628819 | AD42: 0.0043425687 | AE42: 0.0087040977 | AF42: 0.0083679872 | AG42: 0.0028749489 | AH42: 0.0092307344 | AI42: 0.0061666434 | AJ42: 0.016024086 | AK42: 0.0076278244 | AL42: 0.011118882 | AM42: 0.007815027 | AN42: 1.0029663 | AO42: 1.3763978 | AP42: 0.65196054
C43: 列和 | D43: 2.0655695 | E43: 2.1927939 | F43: 2.4234251 | G43: 2.1893074 | H43: 2.2899479 | I43: 2.235019 | J43: 2.0821214 | K43: 2.2089182 | L43: 2.1093792 | M43: 2.2718618 | N43: 3.3162203 | O43: 2.0857882 | P43: 2.1027539 | Q43: 2.1244308 | R43: 2.33714 | S43: 2.5775137 | T43: 2.4661472 | U43: 2.5831234 | V43: 2.7905953 | W43: 2.155518 | X43: 2.0473735 | Y43: 1.896106 | Z43: 2.0962023 | AA43: 1.710518 | AB43: 1.6012836 | AC43: 1.6894871 | AD43: 1.2702009 | AE43: 2.0759925 | AF43: 1.9356384 | AG43: 1.5269829 | AH43: 1.6124103 | AI43: 1.8036842 | AJ43: 1.7569009 | AK43: 1.7974882 | AL43: 1.9538454 | AM43: 3.0986428 | AN43: 1.6328586
C44: 影響力係数 | D44: 0.97840161 | E44: 1.0386642 | F44: 1.1479077 | G44: 1.0370127 | H44: 1.0846833 | I44: 1.058665 | J44: 0.98624179 | K44: 1.0463018 | L44: 0.99915304 | M44: 1.0761164 | N44: 1.5707994 | O44: 0.98797866 | P44: 0.99601481 | Q44: 1.0062826 | R44: 1.1070368 | S44: 1.2208951 | T44: 1.1681439 | U44: 1.2235522 | V44: 1.3218257 | W44: 1.0210077 | X44: 0.9697827 | Y44: 0.89813156 | Z44: 0.99291149 | AA44: 0.81022382 | AB44: 0.7584826 | AC44: 0.80026208 | AD44: 0.60165811 | AE44: 0.98333869 | AF44: 0.91685694 | AG44: 0.72328846 | AH44: 0.76375296 | AI44: 0.854354 | AJ44: 0.83219408 | AK44: 0.85141912 | AL44: 0.9254811 | AM44: 1.4677391 | AN44: 0.77343876

Sheet 逆行列係数表（開放型）
A1: 令和２年（2020年）長野県産業連関表
A2: 第４表 逆行列係数表 [I-(I-M)A]-1型
D3: 1 | E3: 2 | F3: 3 | G3: 4 | H3: 5 | I3: 6 | J3: 7 | K3: 8 | L3: 9 | M3: 10 | N3: 11 | O3: 12 | P3: 13 | Q3: 14 | R3: 15 | S3: 16 | T3: 17 | U3: 18 | V3: 19 | W3: 20 | X3: 21 | Y3: 22 | Z3: 23 | AA3: 24 | AB3: 25 | AC3: 26 | AD3: 27 | AE3: 28 | AF3: 29 | AG3: 30 | AH3: 31 | AI3: 32 | AJ3: 33 | AK3: 34 | AL3: 35 | AM3: 36 | AN3: 37
D4: 01 | E4: 06 | F4: 11 | G4: 15 | H4: 16 | I4: 20 | J4: 21 | K4: 22 | L4: 25 | M4: 26 | N4: 27 | O4: 28 | P4: 29 | Q4: 30 | R4: 31 | S4: 32 | T4: 33 | U4: 34 | V4: 35 | W4: 39 | X4: 41 | Y4: 46 | Z4: 47 | AA4: 48 | AB4: 51 | AC4: 53 | AD4: 55 | AE4: 57 | AF4: 59 | AG4: 61 | AH4: 63 | AI4: 64 | AJ4: 65 | AK4: 66 | AL4: 67 | AM4: 68 | AN4: 69
C5: 統合大分類（37部門） | D5: 農業 | E5: 鉱業 | F5: 飲食料品 | G5: 繊維製品 | H5: パルプ・紙・木製品 | I5: 化学製品 | J5: 石油・石炭製品 | K5: プラスチック・ゴム製品 | L5: 窯業・土石製品 | M5: 鉄鋼 | N5: 非鉄金属 | O5: 金属製品 | P5: はん用機械 | Q5: 生産用機械 | R5: 業務用機械 | S5: 電子部品 | T5: 電気機械 | U5: 情報通信機器 | V5: 輸送機械 | W5: その他の製造工業製品 | X5: 建設 | Y5: 電気・ガス・熱供給 | Z5: 水道 | AA5: 廃棄物処理 | AB5: 商業 | AC5: 金融・保険 | AD5: 不動産 | AE5: 運輸・郵便 | AF5: 情報通信 | AG5: 公務 | AH5: 教育・研究 | AI5: 医療・福祉 | AJ5: 他に分類されない会員制団体 | AK5: 対事業所サービス | AL5: 対個人サービス | AM5: 事務用品 | AN5: 分類不明 | AO5: 行和 | AP5: 感応度係数
A6: 1 | B6: 01 | C6: 農林漁業 | D6: 1.0578674 | E6: 4.5030354e-05 | F6: 0.079798805 | G6: 0.0055438022 | H6: 0.013714949 | I6: 0.0015397602 | J6: 2.4975693e-05 | K6: 0.00039273155 | L6: 0.00025766975 | M6: 3.1131556e-05 | N6: 0.00010373229 | O6: 2.9910274e-05 | P6: 3.263735e-05 | Q6: 2.4549532e-05 | R6: 5.2890669e-05 | S6: 5.5419671e-05 | T6: 5.3994515e-05 | U6: 5.5815576e-05 | V6: 2.1804203e-05 | W6: 0.0032512445 | X6: 0.00073996914 | Y6: 4.9676848e-05 | Z6: 0.00011197207 | AA6: 5.6375872e-05 | AB6: 0.00015191646 | AC6: 7.9381114e-05 | AD6: 2.9544983e-05 | AE6: 5.9421957e-05 | AF6: 0.00020796781 | AG6: 6.1614611e-05 | AH6: 0.0011344389 | AI6: 0.0015239614 | AJ6: 0.0012905277 | AK6: 7.9354422e-05 | AL6: 0.010833984 | AM6: 0.0019174067 | AN6: 0.00012692959 | AO6: 1.1813527 | AP6: 0.91346099
A7: 2 | B7: 06 | C7: 鉱業 | D7: 0.00011872847 | E7: 1.0001533 | F7: 0.00016554549 | G7: 0.0001444996 | H7: 0.00032914371 | I7: 0.00080438664 | J7: 0.0089844494 | K7: 0.00018012657 | L7: 0.0051436954 | M7: 0.00043217996 | N7: 0.0047757894 | O7: 0.00016628079 | P7: 0.00013472314 | Q7: 9.3831981e-05 | R7: 0.00020428251 | S7: 0.00031244329 | T7: 9.9785038e-05 | U7: 6.7832884e-05 | V7: 0.00013317285 | W7: 0.00023054358 | X7: 0.00055486377 | Y7: 0.0085333327 | Z7: 0.00039879805 | AA7: 0.00041377933 | AB7: 0.00016383489 | AC7: 4.8835017e-05 | AD7: 3.3268347e-05 | AE7: 0.00012014759 | AF7: 6.8014779e-05 | AG7: 8.906628e-05 | AH7: 0.00012009775 | AI7: 9.5625142e-05 | AJ7: 5.3009809e-05 | AK7: 4.6597232e-05 | AL7: 0.00021747197 | AM7: 9.7051362e-05 | AN7: 8.1517373e-05 | AO7: 1.0338101 | AP7: 0.79937614
A8: 3 | B8: 11 | C8: 飲食料品 | D8: 0.0091352329 | E8: 2.0862203e-05 | F8: 1.0468613 | G8: 0.00071828525 | H8: 0.00037156916 | I8: 0.002516539 | J8: 1.9279827e-05 | K8: 2.6625358e-05 | L8: 0.00011358922 | M8: 1.4329194e-05 | N8: 1.8490487e-05 | O8: 1.1393655e-05 | P8: 1.6234699e-05 | Q8: 1.2080363e-05 | R8: 1.4526649e-05 | S8: 1.7630836e-05 | T8: 1.3989798e-05 | U8: 1.664527e-05 | V8: 8.3533839e-06 | W8: 0.0003617631 | X8: 3.9611873e-05 | Y8: 2.0086176e-05 | Z8: 3.6986005e-05 | AA8: 1.7409896e-05 | AB8: 5.7367865e-05 | AC8: 3.0839284e-05 | AD8: 1.8342042e-05 | AE8: 2.4146009e-05 | AF8: 0.00021756949 | AG8: 0.00016281122 | AH8: 0.0015586693 | AI8: 0.0020880213 | AJ8: 0.00040419265 | AK8: 5.8083973e-05 | AL8: 0.022103776 | AM8: 7.7424929e-05 | AN8: 0.00087782326 | AO8: 1.0880818 | AP8: 0.84134087
A9: 4 | B9: 15 | C9: 繊維製品 | D9: 0.00012742601 | E9: 0.00013469098 | F9: 6.1906227e-05 | G9: 1.0077944 | H9: 0.00010882011 | I9: 8.2717093e-05 | J9: 3.3304026e-05 | K9: 7.6923023e-05 | L9: 0.00013543592 | M9: 4.8387113e-05 | N9: 0.00010438204 | O9: 5.9279663e-05 | P9: 6.7628346e-05 | Q9: 6.5374263e-05 | R9: 7.2286212e-05 | S9: 0.00017200195 | T9: 0.00011672068 | U9: 6.2915642e-05 | V9: 4.8507201e-05 | W9: 0.00030561696 | X9: 0.0001538235 | Y9: 3.8730016e-05 | Z9: 7.930189e-05 | AA9: 0.00012603341 | AB9: 0.00018409065 | AC9: 8.0173217e-05 | AD9: 1.1678264e-05 | AE9: 7.0710158e-05 | AF9: 5.4718733e-05 | AG9: 0.00019005954 | AH9: 4.240908e-05 | AI9: 0.00016382892 | AJ9: 0.00089728256 | AK9: 9.1578077e-05 | AL9: 0.00020380001 | AM9: 0.00082625634 | AN9: 4.1939651e-05 | AO9: 1.0129351 | AP9: 0.78323492
A10: 5 | B10: 16 | C10: パルプ・紙・木製品 | D10: 0.017875867 | E10: 0.0013016885 | F10: 0.0077542724 | G10: 0.0024388033 | H10: 1.0946101 | I10: 0.0088881409 | J10: 0.00070806355 | K10: 0.0022437981 | L10: 0.0050001475 | M10: 0.00083582815 | N10: 0.0019386469 | O10: 0.001306816 | P10: 0.0010819441 | Q10: 0.00081979404 | R10: 0.0020326346 | S10: 0.0025424707 | T10: 0.0026051946 | U10: 0.0025869793 | V10: 0.00076186495 | W10: 0.018489468 | X10: 0.014577783 | Y10: 0.0011993846 | Z10: 0.0029226859 | AA10: 0.0024177946 | AB10: 0.0032035935 | AC10: 0.0027321231 | AD10: 0.00062614054 | AE10: 0.0022315111 | AF10: 0.0050009958 | AG10: 0.0013937669 | AH10: 0.0036256787 | AI10: 0.00294142 | AJ10: 0.0074396309 | AK10: 0.0022937251 | AL10: 0.0027477025 | AM10: 0.13812402 | AN10: 0.001000786 | AO10: 1.3703013 | AP10: 1.0595623
A11: 6 | B11: 20 | C11: 化学製品 | D11: 0.001143822 | E11: 9.7975533e-05 | F11: 0.00040366443 | G11: 0.002333735 | H11: 0.00063047938 | I11: 1.0052193 | J11: 0.0008454697 | K11: 0.0037358785 | L11: 0.0015559432 | M11: 9.5803915e-05 | N11: 0.00030347849 | O11: 0.00024083825 | P11: 0.00012665654 | Q11: 0.00010867699 | R11: 0.00024329255 | S11: 0.00030282943 | T11: 0.0002583787 | U11: 0.00027750669 | V11: 0.00031282178 | W11: 0.00073781695 | X11: 0.00016664673 | Y11: 3.9641864e-05 | Z11: 0.00026569057 | AA11: 0.0003713938 | AB11: 2.0727795e-05 | AC11: 2.6235597e-05 | AD11: 7.7927539e-06 | AE11: 4.4421194e-05 | AF11: 5.6809676e-05 | AG11: 4.9107793e-05 | AH11: 0.00026080719 | AI11: 0.0032413469 | AJ11: 8.7850229e-05 | AK11: 0.00012128666 | AL11: 0.00023999436 | AM11: 0.0003552044 | AN11: 0.00010362617 | AO11: 1.0244329 | AP11: 0.79212542
A12: 7 | B12: 21 | C12: 石油・石炭製品 | D12: 0.00083854778 | E12: 0.002242789 | F12: 0.00038401154 | G12: 0.00029269143 | H12: 0.00034560261 | I12: 0.0003297502 | J12: 1.0082665 | K12: 0.0001359743 | L12: 0.0014235747 | M12: 0.00060180567 | N12: 0.00040116414 | O12: 0.00032253084 | P12: 0.00016691795 | Q12: 0.00014460902 | R12: 0.00020866559 | S12: 0.00016301697 | T12: 0.00013424664 | U12: 0.00012167196 | V12: 0.00020250537 | W12: 0.00048127515 | X12: 0.0007037405 | Y12: 0.00030614832 | Z12: 0.00066004781 | AA12: 0.00078841594 | AB12: 0.00032752426 | AC12: 0.0002118949 | AD12: 5.2935615e-05 | AE12: 0.0047391724 | AF12: 0.00019349386 | AG12: 0.00043952551 | AH12: 0.00028765787 | AI12: 0.00020202197 | AJ12: 0.00033092971 | AK12: 0.00017836219 | AL12: 0.00044394129 | AM12: 0.00035247447 | AN12: 0.00060306549 | AO12: 1.0280292 | AP12: 0.79490618
A13: 8 | B13: 22 | C13: プラスチック・ゴム製品 | D13: 0.0019354289 | E13: 0.00075249542 | F13: 0.0037064763 | G13: 0.001377752 | H13: 0.0020234906 | I13: 0.0057750112 | J13: 0.00022000374 | K13: 1.0232836 | L13: 0.0005979664 | M13: 0.00017302626 | N13: 0.0010546465 | O13: 0.00045338523 | P13: 0.0014717337 | Q13: 0.0022355907 | R13: 0.0047343742 | S13: 0.0016174348 | T13: 0.0029862895 | U13: 0.0050796025 | V13: 0.0052732349 | W13: 0.0053445174 | X13: 0.0017662234 | Y13: 0.00030436498 | Z13: 0.0049349939 | AA13: 0.0024228945 | AB13: 0.00085154585 | AC13: 0.00055872721 | AD13: 0.00015972403 | AE13: 0.0008759281 | AF13: 0.0006301412 | AG13: 0.00045889758 | AH13: 0.00077084059 | AI13: 0.0004579335 | AJ13: 0.0011327225 | AK13: 0.0015645377 | AL13: 0.00065508078 | AM13: 0.0056303116 | AN13: 0.00043488166 | AO13: 1.0937058 | AP13: 0.84568951
A14: 9 | B14: 25 | C14: 窯業・土石製品 | D14: 0.0013798094 | E14: 0.00026677487 | F14: 0.0010790159 | G14: 0.0003286209 | H14: 0.00074812088 | I14: 0.0047307589 | J14: 0.0092869331 | K14: 0.0012661391 | L14: 1.0315939 | M14: 0.0021791502 | N14: 0.0079824711 | O14: 0.00229994 | P14: 0.0032049851 | Q14: 0.0016837957 | R14: 0.016633731 | S14: 0.017406861 | T14: 0.0030592822 | U14: 0.0013467792 | V14: 0.001054612 | W14: 0.0022432818 | X14: 0.018657221 | Y14: 0.00056999627 | Z14: 0.003160649 | AA14: 0.00037887548 | AB14: 0.00026465562 | AC14: 0.00020249929 | AD14: 0.00032595121 | AE14: 0.00045866018 | AF14: 0.00025740116 | AG14: 0.00036095324 | AH14: 0.00090797621 | AI14: 0.00050708136 | AJ14: 0.00034338116 | AK14: 0.00062350073 | AL14: 0.00061530325 | AM14: 0.0023058158 | AN14: 0.00134463 | AO14: 1.1410596 | AP14: 0.88230499
